Traceback (most recent call last):
  File "/opt/hostedtoolcache/Python/3.8.8/x64/lib/python3.8/site-packages/jupyter_cache/executors/utils.py", line 51, in single_nb_execution
    executenb(
  File "/opt/hostedtoolcache/Python/3.8.8/x64/lib/python3.8/site-packages/nbclient/client.py", line 1112, in execute
    return NotebookClient(nb=nb, resources=resources, km=km, **kwargs).execute()
  File "/opt/hostedtoolcache/Python/3.8.8/x64/lib/python3.8/site-packages/nbclient/util.py", line 74, in wrapped
    return just_run(coro(*args, **kwargs))
  File "/opt/hostedtoolcache/Python/3.8.8/x64/lib/python3.8/site-packages/nbclient/util.py", line 53, in just_run
    return loop.run_until_complete(coro)
  File "/opt/hostedtoolcache/Python/3.8.8/x64/lib/python3.8/asyncio/base_events.py", line 616, in run_until_complete
    return future.result()
  File "/opt/hostedtoolcache/Python/3.8.8/x64/lib/python3.8/site-packages/nbclient/client.py", line 553, in async_execute
    await self.async_execute_cell(
  File "/opt/hostedtoolcache/Python/3.8.8/x64/lib/python3.8/site-packages/nbclient/client.py", line 857, in async_execute_cell
    self._check_raise_for_error(cell, exec_reply)
  File "/opt/hostedtoolcache/Python/3.8.8/x64/lib/python3.8/site-packages/nbclient/client.py", line 760, in _check_raise_for_error
    raise CellExecutionError.from_cell_and_msg(cell, exec_reply_content)
nbclient.exceptions.CellExecutionError: An error occurred while executing the following cell:
------------------
# Focus on one parameter

list_input = ["Pump.rh_coef[1]"]
doe_data = np.array([[xx] for xx in dic_range[list_input[0]]])
list_df = simulate_on_doe(list_input, doe_data, path_fmu, **kwargs)

p = figure(plot_width=400, plot_height=400)
list_color = [""]
for (df, value, color) in zip(list_df, doe_data, colormap):
    p.line(df.index, df[list_output[0]], legend_label=str(value[0]), color=color)
p.legend.location = "bottom_right"
p.legend.title = list_input[0]
p.xaxis[0].axis_label = 'Time (s)'
p.yaxis[0].axis_label = 'Mass flow rate (kg/s)'
p.legend.click_policy="hide"
p.title.text = 'Click on legend entries to hide the corresponding lines'
show(p)
------------------

[0;31m---------------------------------------------------------------------------[0m
[0;31mNameError[0m                                 Traceback (most recent call last)
[0;32m<ipython-input-1-671262e96134>[0m in [0;36msimulate_on_doe[0;34m(list_input, doe_data, path_fmu, **kwargs)[0m
[1;32m     54[0m             [0mresult[0m [0;34m=[0m [0mfmpy[0m[0;34m.[0m[0msimulate_fmu[0m[0;34m([0m[0mpath_fmu[0m[0;34m,[0m [0;34m**[0m[0mkwargs[0m[0;34m)[0m[0;34m[0m[0;34m[0m[0m
[0;32m---> 55[0;31m             [0mresult[0m [0;34m=[0m [0mpd[0m[0;34m.[0m[0mDataFrame[0m[0;34m([0m[0mresult[0m[0;34m)[0m[0;34m[0m[0;34m[0m[0m
[0m[1;32m     56[0m             [0mresult[0m [0;34m=[0m [0mresult[0m[0;34m.[0m[0mset_index[0m[0;34m([0m[0;34m"time"[0m[0;34m)[0m[0;34m[0m[0;34m[0m[0m

[0;31mNameError[0m: name 'pd' is not defined

During handling of the above exception, another exception occurred:

[0;31mNameError[0m                                 Traceback (most recent call last)
[0;32m<ipython-input-2-634b4bcbbb9d>[0m in [0;36m<module>[0;34m[0m
[1;32m      3[0m [0mlist_input[0m [0;34m=[0m [0;34m[[0m[0;34m"Pump.rh_coef[1]"[0m[0;34m][0m[0;34m[0m[0;34m[0m[0m
[1;32m      4[0m [0mdoe_data[0m [0;34m=[0m [0mnp[0m[0;34m.[0m[0marray[0m[0;34m([0m[0;34m[[0m[0;34m[[0m[0mxx[0m[0;34m][0m [0;32mfor[0m [0mxx[0m [0;32min[0m [0mdic_range[0m[0;34m[[0m[0mlist_input[0m[0;34m[[0m[0;36m0[0m[0;34m][0m[0;34m][0m[0;34m][0m[0;34m)[0m[0;34m[0m[0;34m[0m[0m
[0;32m----> 5[0;31m [0mlist_df[0m [0;34m=[0m [0msimulate_on_doe[0m[0;34m([0m[0mlist_input[0m[0;34m,[0m [0mdoe_data[0m[0;34m,[0m [0mpath_fmu[0m[0;34m,[0m [0;34m**[0m[0mkwargs[0m[0;34m)[0m[0;34m[0m[0;34m[0m[0m
[0m[1;32m      6[0m [0;34m[0m[0m
[1;32m      7[0m [0mp[0m [0;34m=[0m [0mfigure[0m[0;34m([0m[0mplot_width[0m[0;34m=[0m[0;36m400[0m[0;34m,[0m [0mplot_height[0m[0;34m=[0m[0;36m400[0m[0;34m)[0m[0;34m[0m[0;34m[0m[0m

[0;32m<ipython-input-1-671262e96134>[0m in [0;36msimulate_on_doe[0;34m(list_input, doe_data, path_fmu, **kwargs)[0m
[1;32m     59[0m         [0;32mexcept[0m [0mException[0m [0;32mas[0m [0mexc[0m[0;34m:[0m[0;34m[0m[0;34m[0m[0m
[1;32m     60[0m             [0mprint[0m[0;34m([0m[0mexc[0m[0;34m)[0m[0;34m[0m[0;34m[0m[0m
[0;32m---> 61[0;31m             [0mresult[0m [0;34m=[0m [0mpd[0m[0;34m.[0m[0mDataFrame[0m[0;34m([0m[0;34m[[0m[0mnp[0m[0;34m.[0m[0mNaN[0m[0;34m][0m[0;34m)[0m[0;34m[0m[0;34m[0m[0m
[0m[1;32m     62[0m         [0mlist_result[0m[0;34m.[0m[0mappend[0m[0;34m([0m[0mresult[0m[0;34m)[0m[0;34m[0m[0;34m[0m[0m
[1;32m     63[0m     [0;32mreturn[0m [0mlist_result[0m[0;34m[0m[0;34m[0m[0m

[0;31mNameError[0m: name 'pd' is not defined
NameError: name 'pd' is not defined

